<?xml version="1.0"?>
<robot xmlns:xacro="http://www.ros.org/wiki/xacro">

    <xacro:macro name="mrobot_standoff_2in" params="parent number x_loc y_loc z_loc">
        <joint name="standoff_2in_${number}_joint" type="fixed">
            <origin xyz="${x_loc} ${y_loc} ${z_loc}" rpy="0 0 0" />
            <parent link="${parent}"/>
            <child link="standoff_2in_${number}_link" />
        </joint>

        <link name="standoff_2in_${number}_link">
            <inertial>
                <mass value="0.001" />
                <origin xyz="0 0 0" />
                <inertia ixx="0.0001" ixy="0.0" ixz="0.0"
                         iyy="0.0001" iyz="0.0"
                         izz="0.0001" />
            </inertial>

            <visual>
                <origin xyz=" 0 0 0 " rpy="0 0 0" />
                <geometry>
                    <box size="0.01 0.01 0.07" />
                </geometry>
                <material name="black">
                    <color rgba="0.16 0.17 0.15 0.9"/>
                </material>
            </visual>

            <collision>
                <origin xyz="0.0 0.0 0.0" rpy="0 0 0" />
                <geometry>
                    <box size="0.01 0.01 0.07" />
                </geometry>
            </collision>
        </link>
    </xacro:macro>


    <xacro:macro name="mrobot_body">

         <link name="base_footprint">
            <visual>
                <origin xyz="0 0 0" rpy="0 0 0" />
                <geometry>
                    <box size="0.001 0.001 0.001" />
                </geometry>
            </visual>
        </link>

        <joint name="base_footprint_joint" type="fixed">
            <origin xyz="0 0 0.033" rpy="0 0 0" />        
            <parent link="base_footprint"/>
            <child link="base_link" />
        </joint>

        <link name="base_link">
            <inertial>
                <mass value="2"/>
                <origin xyz="0 0 0.0"/>
                <inertia ixx="0.01" ixy="0.0" ixz="0.0"
                         iyy="0.01" iyz="0.0" izz="0.5"/>
            </inertial>
            <visual>
                <origin xyz=" 0 0 0" rpy="0 0 0" />
                <geometry>
                    <cylinder length="0.005" radius="0.13"/>
                </geometry>
                <material name="yellow">
                    <color rgba="1 0.4 0 1"/>
                </material>
            </visual>
            <collision>
                <origin xyz="0 0 0" rpy="0 0 0"/>
                <geometry>
                    <cylinder length="0.005" radius="0.13"/>
                </geometry>
            </collision>
        </link>

        <joint name="base_left_motor_joint" type="fixed">
            <origin xyz="-0.055 0.075 0" rpy="0 0 0" />        
            <parent link="base_link"/>
            <child link="left_motor" />
        </joint>

        <link name="left_motor">
            <visual>
                <origin xyz="0 0 0" rpy="1.5707 0 0" />
                <geometry>
                    <cylinder radius="0.02" length = "0.08"/>
                </geometry>
                <material name="gray">
                    <color rgba="0.75 0.75 0.75 1"/>
                </material>
            </visual>
        </link>

        <joint name="left_wheel_joint" type="continuous">
            <origin xyz="0 0.0485 0" rpy="0 0 0"/>
            <parent link="left_motor"/>
            <child link="left_wheel_link"/>
            <axis xyz="0 1 0"/>
        </joint>

        <link name="left_wheel_link">
            <visual>
                <origin xyz="0 0 0" rpy="1.5707 0 0" />
                <geometry>
                    <cylinder radius="0.033" length = "0.017"/>
                </geometry>
                <material name="white">
                    <color rgba="1 1 1 0.9"/>
                </material>
            </visual>
        </link>

        <joint name="base_right_motor_joint" type="fixed">
            <origin xyz="-0.055 -0.075 0" rpy="0 0 0" />        
            <parent link="base_link"/>
            <child link="right_motor" />
        </joint>

        <link name="right_motor">
            <visual>
                <origin xyz="0 0 0" rpy="1.5707 0 0" />
                <geometry>
                    <cylinder radius="0.02" length = "0.08" />
                </geometry>
                <material name="gray">
                    <color rgba="0.75 0.75 0.75 1"/>
                </material>
            </visual>
        </link>

        <joint name="right_wheel_joint" type="continuous">
            <origin xyz="0 -0.0485 0" rpy="0 0 0"/>
            <parent link="right_motor"/>
            <child link="right_wheel_link"/>
            <axis xyz="0 1 0"/>
        </joint>

        <link name="right_wheel_link">
            <visual>
                <origin xyz="0 0 0" rpy="1.5707 0 0" />
                <geometry>
                    <cylinder radius="0.033" length = "0.017"/>
                </geometry>
                <material name="white">
                    <color rgba="1 1 1 0.9"/>
                </material>
            </visual>
        </link>

        <joint name="front_caster_joint" type="fixed">
            <origin xyz="0.1135 0 -0.0165" rpy="0 0 0"/>
            <parent link="base_link"/>
            <child link="front_caster_link"/>

        </joint>

        <link name="front_caster_link">
            <visual>
                <origin xyz="0 0 0" rpy="1.5707 0 0"/>
                <geometry>
                    <sphere radius="0.0165" />
                </geometry>
                <material name="black">
                    <color rgba="0 0 0 0.95"/>
                </material>
            </visual>
        </link>

        <mrobot_standoff_2in parent="base_link" number="1" x_loc="-${0.12/2 + 0.03}" y_loc="-${0.10 - 0.03}" z_loc="${0.07/2}"/>
        <mrobot_standoff_2in parent="base_link" number="2" x_loc="-${0.12/2 + 0.03}" y_loc="${0.12 - 0.03}" z_loc="${0.07/2}"/>
        <mrobot_standoff_2in parent="base_link" number="3" x_loc="${0.12/2}" y_loc="-${0.12}" z_loc="${0.07/2}"/>
        <mrobot_standoff_2in parent="base_link" number="4" x_loc="${0.12/2}" y_loc="${0.12}" z_loc="${0.07/2}"/>

        <joint name="plate_1_joint" type="fixed">
            <origin xyz="0 0 0.07" rpy="0 0 0" />
            <parent link="base_link"/>
            <child link="plate_1_link" />
        </joint>

        <link name="plate_1_link">
            <inertial>
                <mass value="0.01"/>
                <origin xyz="0 0 0.0"/>
                <inertia ixx="0.001" ixy="0.0" ixz="0.0"
                         iyy="0.01" iyz="0.0" izz="0.001"/>
            </inertial>
            <visual>
                <origin xyz=" 0 0 0" rpy="0 0 0" />
                <geometry>
                    <cylinder length="0.005" radius="0.13"/>
                </geometry>
                <material name="yellow">
                    <color rgba="1 0.4 0 1"/>
                </material>
            </visual>
            <collision>
                <origin xyz="0 0 0" rpy="0 0 0"/>
                <geometry>
                    <cylinder length="0.005" radius="0.13"/>
                </geometry>
            </collision>
        </link>



    </xacro:macro>

</robot>
